Workbook

Sheet Dinâmica
A3: Rótulos de Linha | B3: Soma de Valor em Atraso (R$) | C3: %
A4: 1 a 30 dias | B4: 848207.35 | C4: =GETPIVOTDATA("Valor em Atraso (R$)",$A$3,"Aging Alexandria","1 a 30 dias")/GETPIVOTDATA("Valor em Atraso (R$)",$A$3) -> 0.49991494
A5: 31 a 60 dias | B5: 390367.3 | C5: =GETPIVOTDATA("Valor em Atraso (R$)",$A$3,"Aging Alexandria","31 a 60 dias")/GETPIVOTDATA("Valor em Atraso (R$)",$A$3) -> 0.23007399
A6: 61 a 90 dias | B6: 182066.03 | C6: =GETPIVOTDATA("Valor em Atraso (R$)",$A$3,"Aging Alexandria","61 a 90 dias")/GETPIVOTDATA("Valor em Atraso (R$)",$A$3) -> 0.10730575
A7: Maior que 90 | B7: 276062.65 | C7: =GETPIVOTDATA("Valor em Atraso (R$)",$A$3,"Aging Alexandria","Maior que 90")/GETPIVOTDATA("Valor em Atraso (R$)",$A$3) -> 0.16270532
A8: (vazio)
A9: Total Geral | B9: 1696703.3

Sheet Base EDP
A1: ID Cobranca | B1: Status Fat | C1: Núm Inst | D1: CNPJ / CPF | E1: Razão Social / Nome | F1: Endereço | G1: ID do Contrato | H1: referência | I1: Mês de Referência | J1: Valor da Cobrança (R$) | K1: Vlr Adicional - Total | L1: Valor em Atraso (R$) | M1: Valor Pago (R$) | N1: Invoice Num | O1: Data Emissão | P1: Data Vencimento | Q1: Data Pagamento | R1: Dias Atraso | S1: Tp Inscr | T1: STATUS EDP | U1: STATUS ALEXANDRIA | V1: cod venda | W1: status | X1: usina_pg | Y1: Status FAT - LF | Z1: FINAL | AA1: Nome | AB1: Representante | AC1: Tipo Medição | AD1: Fat.Agrup. | AE1: Aging edp | AF1: UUID | AG1: Vencimento Lex | AH1: Aging Alexandria | AI1: AVISO_VENCIMENTO_2DIAS | AJ1: AVISO_VENCIMENTO_5DIAS | AK1: FATURA_ENVIO | AL1: FATURA_INADIMPLENCIA | AM1: FATURA_VENCE_HOJE | AN1: FATURA_VENCIDA_10_DIAS | AO1: FATURA_VENCIDA_14_DIAS | AP1: FATURA_VENCIDA_17_DIAS | AQ1: FATURA_VENCIDA_21_DIAS | AR1: FATURA_VENCIDA_25_DIAS | AS1: FATURA_VENCIDA_30_DIAS | AT1: FATURA_VENCIDA_3_DIAS | AU1: FATURA_VENCIDA_5_DIAS | AV1: FATURA_VENCIDA_7_DIAS
A2: COB-243058 | B2: Faturado | C2: 5315550 | D2: 40261800000180 | E2: VENTURA SERVICOS MEDICOS LTDA | F2: Rua Doutor José Peroba 325 SL-1406 Stiep Salvador BA 41770-235 | G2: ADE-17650-X3P0X6 | H2: 46082 | I2: 202603 | J2: 248.50894 | L2: 248.51 | N2: 90520454 | O2: 46101 | P2: 46111 | R2: 15 | S2: 1 - CNPJ | T2: Em aberto - Vencido | U2: Em aberto - Vencido | V2: U41JLVB | W2: 6 | X2: false | Y2: 6 | Z2: Em aberto - Vencido | AA2: ASSOCIAÇÃO BA ? L1 | AB2: 35.686.965/0001-64 - ALEXANDRIA TECH | AC2: Estimado | AE2: 1 a 30 dias | AF2: 8522cc6f-66f1-4a8e-99bf-7b04f8b2a8aa | AG2: 46111 | AH2: 1 a 30 dias | AI2: =_xlfn.XLOOKUP(Tabela5[[#This Row],[UUID]],Planilha2!$A:$A,Planilha2!B:B,"") -> 1 | AJ2: =_xlfn.XLOOKUP(Tabela5[[#This Row],[UUID]],Planilha2!$A:$A,Planilha2!C:C,"") -> 1 | AK2: =_xlfn.XLOOKUP(Tabela5[[#This Row],[UUID]],Planilha2!$A:$A,Planilha2!D:D,"") -> 8 | AL2: =_xlfn.XLOOKUP(Tabela5[[#This Row],[UUID]],Planilha2!$A:$A,Planilha2!E:E,"") -> 0 | AM2: =_xlfn.XLOOKUP(Tabela5[[#This Row],[UUID]],Planilha2!$A:$A,Planilha2!F:F,"") -> 1 | AN2: =_xlfn.XLOOKUP(Tabela5[[#This Row],[UUID]],Planilha2!$A:$A,Planilha2!G:G,"") -> 1 | AO2: =_xlfn.XLOOKUP(Tabela5[[#This Row],[UUID]],Planilha2!$A:$A,Planilha2!H:H,"") -> 1 | AP2: =_xlfn.XLOOKUP(Tabela5[[#This Row],[UUID]],Planilha2!$A:$A,Planilha2!I:I,"") -> 0 | AQ2: =_xlfn.XLOOKUP(Tabela5[[#This Row],[UUID]],Planilha2!$A:$A,Planilha2!J:J,"") -> 0 | AR2: =_xlfn.XLOOKUP(Tabela5[[#This Row],[UUID]],Planilha2!$A:$A,Planilha2!K:K,"") -> 0 | AS2: =_xlfn.XLOOKUP(Tabela5[[#This Row],[UUID]],Planilha2!$A:$A,Planilha2!L:L,"") -> 0 | AT2: =_xlfn.XLOOKUP(Tabela5[[#This Row],[UUID]],Planilha2!$A:$A,Planilha2!M:M,"") -> 1 | AU2: =_xlfn.XLOOKUP(Tabela5[[#This Row],[UUID]],Planilha2!$A:$A,Planilha2!N:N,"") -> 1 | AV2: =_xlfn.XLOOKUP(Tabela5[[#This Row],[UUID]],Planilha2!$A:$A,Planilha2!O:O,"") -> 1
A3: COB-243042 | B3: Faturado | C3: 648143 | D3: 976482568 | E3: GERALDO CARDOSO DOS SANTOS | F3: RUA MONTE DAS OLIVEIRAS 34 Alto do Cristo Caetité BA 46400000 | G3: ADE-17365-S4H7T6 | H3: 46082 | I3: 202603 | J3: 123.18638 | L3: 123.19 | N3: 90520370 | O3: 46101 | P3: 46111 | R3: 15 | S3: 2 - CPF | T3: Em aberto - Vencido | U3: Em aberto - Vencido | V3: 77JE70K | W3: 6 | X3: false | Y3: 6 | Z3: Em aberto - Vencido | AA3: ASSOCIAÇÃO BA ? L1 | AB3: 35.686.965/0001-64 - ALEXANDRIA TECH | AC3: Estimado | AE3: 1 a 30 dias | AF3: 60e65356-e6f9-483a-ac37-ce26512ba3ff | AG3: 46111 | AH3: 1 a 30 dias | AI3: =_xlfn.XLOOKUP(Tabela5[[#This Row],[UUID]],Planilha2!$A:$A,Planilha2!B:B,"") -> 1 | AJ3: =_xlfn.XLOOKUP(Tabela5[[#This Row],[UUID]],Planilha2!$A:$A,Planilha2!C:C,"") -> 1 | AK3: =_xlfn.XLOOKUP(Tabela5[[#This Row],[UUID]],Planilha2!$A:$A,Planilha2!D:D,"") -> 1 | AL3: =_xlfn.XLOOKUP(Tabela5[[#This Row],[UUID]],Planilha2!$A:$A,Planilha2!E:E,"") -> 0 | AM3: =_xlfn.XLOOKUP(Tabela5[[#This Row],[UUID]],Planilha2!$A:$A,Planilha2!F:F,"") -> 1 | AN3: =_xlfn.XLOOKUP(Tabela5[[#This Row],[UUID]],Planilha2!$A:$A,Planilha2!G:G,"") -> 1 | AO3: =_xlfn.XLOOKUP(Tabela5[[#This Row],[UUID]],Planilha2!$A:$A,Planilha2!H:H,"") -> 1 | AP3: =_xlfn.XLOOKUP(Tabela5[[#This Row],[UUID]],Planilha2!$A:$A,Planilha2!I:I,"") -> 0 | AQ3: =_xlfn.XLOOKUP(Tabela5[[#This Row],[UUID]],Planilha2!$A:$A,Planilha2!J:J,"") -> 0 | AR3: =_xlfn.XLOOKUP(Tabela5[[#This Row],[UUID]],Planilha2!$A:$A,Planilha2!K:K,"") -> 0 | AS3: =_xlfn.XLOOKUP(Tabela5[[#This Row],[UUID]],Planilha2!$A:$A,Planilha2!L:L,"") -> 0 | AT3: =_xlfn.XLOOKUP(Tabela5[[#This Row],[UUID]],Planilha2!$A:$A,Planilha2!M:M,"") -> 1 | AU3: =_xlfn.XLOOKUP(Tabela5[[#This Row],[UUID]],Planilha2!$A:$A,Planilha2!N:N,"") -> 1 | AV3: =_xlfn.XLOOKUP(Tabela5[[#This Row],[UUID]],Planilha2!$A:$A,Planilha2!O:O,"") -> 1
A4: COB-243024 | B4: Faturado | C4: 560430 | D4: 85891658500 | E4: FLAVIANE ARAUJO MOREIRA | F4: RUA E 20 SANTA TEREZA Brumado BA 46100-000 | G4: ADE-17197-V7Q1L0 | H4: 46082 | I4: 202603 | J4: 133.15522 | L4: 133.16 | N4: 90520498 | O4: 46101 | P4: 46111 | R4: 15 | S4: 2 - CPF | T4: Em aberto - Vencido | U4: Em aberto - Vencido | V4: X1AQCA7 | W4: 6 | X4: false | Y4: 6 | Z4: Em aberto - Vencido | AA4: ASSOCIAÇÃO BA ? L1 | AB4: 35.686.965/0001-64 - ALEXANDRIA TECH | AC4: Estimado | AE4: 1 a 30 dias | AF4: 1b1353ff-2679-4e66-a4e1-8e6cb9807f4d | AG4: 46111 | AH4: 1 a 30 dias | AI4: =_xlfn.XLOOKUP(Tabela5[[#This Row],[UUID]],Planilha2!$A:$A,Planilha2!B:B,"") -> 1 | AJ4: =_xlfn.XLOOKUP(Tabela5[[#This Row],[UUID]],Planilha2!$A:$A,Planilha2!C:C,"") -> 1 | AK4: =_xlfn.XLOOKUP(Tabela5[[#This Row],[UUID]],Planilha2!$A:$A,Planilha2!D:D,"") -> 1 | AL4: =_xlfn.XLOOKUP(Tabela5[[#This Row],[UUID]],Planilha2!$A:$A,Planilha2!E:E,"") -> 0 | AM4: =_xlfn.XLOOKUP(Tabela5[[#This Row],[UUID]],Planilha2!$A:$A,Planilha2!F:F,"") -> 1 | AN4: =_xlfn.XLOOKUP(Tabela5[[#This Row],[UUID]],Planilha2!$A:$A,Planilha2!G:G,"") -> 1 | AO4: =_xlfn.XLOOKUP(Tabela5[[#This Row],[UUID]],Planilha2!$A:$A,Planilha2!H:H,"") -> 1 | AP4: =_xlfn.XLOOKUP(Tabela5[[#This Row],[UUID]],Planilha2!$A:$A,Planilha2!I:I,"") -> 0 | AQ4: =_xlfn.XLOOKUP(Tabela5[[#This Row],[UUID]],Planilha2!$A:$A,Planilha2!J:J,"") -> 0 | AR4: =_xlfn.XLOOKUP(Tabela5[[#This Row],[UUID]],Planilha2!$A:$A,Planilha2!K:K,"") -> 0 | AS4: =_xlfn.XLOOKUP(Tabela5[[#This Row],[UUID]],Planilha2!$A:$A,Planilha2!L:L,"") -> 0 | AT4: =_xlfn.XLOOKUP(Tabela5[[#This Row],[UUID]],Planilha2!$A:$A,Planilha2!M:M,"") -> 1 | AU4: =_xlfn.XLOOKUP(Tabela5[[#This Row],[UUID]],Planilha2!$A:$A,Planilha2!N:N,"") -> 1 | AV4: =_xlfn.XLOOKUP(Tabela5[[#This Row],[UUID]],Planilha2!$A:$A,Planilha2!O:O,"") -> 1
A5: COB-120638 | B5: Faturado | C5: 2680126150 | D5: 6377392133 | E5: FELLIPE BITENCOURT DE OLIVEIRA | F5: RUA PAQUETA, Q. 38, L. 10-12, S/N PARQUE ARAGUARI CEP: 72880000 CIDADE OCIDENTAL GO BRASIL | G5: ADE-11135-V3G8V8 | H5: 45778 | I5: 202505 | J5: 64.47272 | L5: 64.47 | N5: 90305430 | O5: 45831 | P5: 45841 | R5: 285 | S5: 2 - CPF | T5: Em aberto - Vencido | U5: Em aberto - Vencido | V5: 632TDKU | W5: 6 | X5: false | Y5: 6 | Z5: Em aberto - Vencido | AA5: ASSOCIAÇÃO GO-L1 | AB5: 35.686.965/0001-64 - ALEXANDRIA TECH | AE5: 171 a 450 dias | AF5: ac63bd63-376f-4148-b396-b2f86a95d9a3 | AG5: 46020 | AH5: Maior que 90 | AI5: =_xlfn.XLOOKUP(Tabela5[[#This Row],[UUID]],Planilha2!$A:$A,Planilha2!B:B,"") -> 0 | AJ5: =_xlfn.XLOOKUP(Tabela5[[#This Row],[UUID]],Planilha2!$A:$A,Planilha2!C:C,"") -> 0 | AK5: =_xlfn.XLOOKUP(Tabela5[[#This Row],[UUID]],Planilha2!$A:$A,Planilha2!D:D,"") -> 1 | AL5: =_xlfn.XLOOKUP(Tabela5[[#This Row],[UUID]],Planilha2!$A:$A,Planilha2!E:E,"") -> 2 | AM5: =_xlfn.XLOOKUP(Tabela5[[#This Row],[UUID]],Planilha2!$A:$A,Planilha2!F:F,"") -> 0 | AN5: =_xlfn.XLOOKUP(Tabela5[[#This Row],[UUID]],Planilha2!$A:$A,Planilha2!G:G,"") -> 0 | AO5: =_xlfn.XLOOKUP(Tabela5[[#This Row],[UUID]],Planilha2!$A:$A,Planilha2!H:H,"") -> 0 | AP5: =_xlfn.XLOOKUP(Tabela5[[#This Row],[UUID]],Planilha2!$A:$A,Planilha2!I:I,"") -> 1 | AQ5: =_xlfn.XLOOKUP(Tabela5[[#This Row],[UUID]],Planilha2!$A:$A,Planilha2!J:J,"") -> 1 | AR5: =_xlfn.XLOOKUP(Tabela5[[#This Row],[UUID]],Planilha2!$A:$A,Planilha2!K:K,"") -> 1 | AS5: =_xlfn.XLOOKUP(Tabela5[[#This Row],[UUID]],Planilha2!$A:$A,Planilha2!L:L,"") -> 1 | AT5: =_xlfn.XLOOKUP(Tabela5[[#This Row],[UUID]],Planilha2!$A:$A,Planilha2!M:M,"") -> 0 | AU5: =_xlfn.XLOOKUP(Tabela5[[#This Row],[UUID]],Planilha2!$A:$A,Planilha2!N:N,"") -> 0 | AV5: =_xlfn.XLOOKUP(Tabela5[[#This Row],[UUID]],Planilha2!$A:$A,Planilha2!O:O,"") -> 0
A6: COB-242944 | B6: Faturado | C6: 1411413 | D6: 2086578512 | E6: MIRELIA NUNES PEREIRA | F6: RUA DA PAROQUIA 170 CENTRO Érico Cardoso BA 46180-000 | G6: ADE-16846-B0T3S5 | H6: 46082 | I6: 202603 | J6: 148.82054 | L6: 148.82 | N6: 90520399 | O6: 46101 | P6: 46111 | R6: 15 | S6: 2 - CPF | T6: Em aberto - Vencido | U6: Em aberto - Vencido | V6: O3M6EB9 | W6: 6 | X6: false | Y6: 6 | Z6: Em aberto - Vencido | AA6: ASSOCIAÇÃO BA ? L1 | AB6: 35.686.965/0001-64 - ALEXANDRIA TECH | AC6: Estimado | AE6: 1 a 30 dias | AF6: c874ae86-bfe5-48a1-84c3-350d7091e666 | AG6: 46111 | AH6: 1 a 30 dias | AI6: =_xlfn.XLOOKUP(Tabela5[[#This Row],[UUID]],Planilha2!$A:$A,Planilha2!B:B,"") -> 1 | AJ6: =_xlfn.XLOOKUP(Tabela5[[#This Row],[UUID]],Planilha2!$A:$A,Planilha2!C:C,"") -> 1 | AK6: =_xlfn.XLOOKUP(Tabela5[[#This Row],[UUID]],Planilha2!$A:$A,Planilha2!D:D,"") -> 1 | AL6: =_xlfn.XLOOKUP(Tabela5[[#This Row],[UUID]],Planilha2!$A:$A,Planilha2!E:E,"") -> 0 | AM6: =_xlfn.XLOOKUP(Tabela5[[#This Row],[UUID]],Planilha2!$A:$A,Planilha2!F:F,"") -> 1 | AN6: =_xlfn.XLOOKUP(Tabela5[[#This Row],[UUID]],Planilha2!$A:$A,Planilha2!G:G,"") -> 1 | AO6: =_xlfn.XLOOKUP(Tabela5[[#This Row],[UUID]],Planilha2!$A:$A,Planilha2!H:H,"") -> 1 | AP6: =_xlfn.XLOOKUP(Tabela5[[#This Row],[UUID]],Planilha2!$A:$A,Planilha2!I:I,"") -> 0 | AQ6: =_xlfn.XLOOKUP(Tabela5[[#This Row],[UUID]],Planilha2!$A:$A,Planilha2!J:J,"") -> 0 | AR6: =_xlfn.XLOOKUP(Tabela5[[#This Row],[UUID]],Planilha2!$A:$A,Planilha2!K:K,"") -> 0 | AS6: =_xlfn.XLOOKUP(Tabela5[[#This Row],[UUID]],Planilha2!$A:$A,Planilha2!L:L,"") -> 0 | AT6: =_xlfn.XLOOKUP(Tabela5[[#This Row],[UUID]],Planilha2!$A:$A,Planilha2!M:M,"") -> 1 | AU6: =_xlfn.XLOOKUP(Tabela5[[#This Row],[UUID]],Planilha2!$A:$A,Planilha2!N:N,"") -> 1 | AV6: =_xlfn.XLOOKUP(Tabela5[[#This Row],[UUID]],Planilha2!$A:$A,Planilha2!O:O,"") -> 1
A7: COB-242941 | B7: Faturado | C7: 40257119 | D7: 1870686586 | E7: JUSCELIA DOS SANTOS DIAS ALMEIDA | F7: RUA PRINCESA LEOPOLDINA 197 FT DR JURACY PIRES GOMES Brumado BA 46100-000 | G7: ADE-16812-B1F5D3 | H7: 46082 | I7: 202603 | J7: 145.9723 | L7: 145.97 | N7: 90520521 | O7: 46101 | P7: 46111 | R7: 15 | S7: 2 - CPF | T7: Em aberto - Vencido | U7: Em aberto - Vencido | V7: PCWO0XR | W7: 6 | X7: false | Y7: 6 | Z7: Em aberto - Vencido | AA7: ASSOCIAÇÃO BA ? L1 | AB7: 35.686.965/0001-64 - ALEXANDRIA TECH | AC7: Estimado | AE7: 1 a 30 dias | AF7: 4fd06ac5-aa94-4d20-9802-e4b62c886713 | AG7: 46115 | AH7: 1 a 30 dias | AI7: =_xlfn.XLOOKUP(Tabela5[[#This Row],[UUID]],Planilha2!$A:$A,Planilha2!B:B,"") -> 1 | AJ7: =_xlfn.XLOOKUP(Tabela5[[#This Row],[UUID]],Planilha2!$A:$A,Planilha2!C:C,"") -> 1 | AK7: =_xlfn.XLOOKUP(Tabela5[[#This Row],[UUID]],Planilha2!$A:$A,Planilha2!D:D,"") -> 7 | AL7: =_xlfn.XLOOKUP(Tabela5[[#This Row],[UUID]],Planilha2!$A:$A,Planilha2!E:E,"") -> 0 | AM7: =_xlfn.XLOOKUP(Tabela5[[#This Row],[UUID]],Planilha2!$A:$A,Planilha2!F:F,"") -> 1 | AN7: =_xlfn.XLOOKUP(Tabela5[[#This Row],[UUID]],Planilha2!$A:$A,Planilha2!G:G,"") -> 1 | AO7: =_xlfn.XLOOKUP(Tabela5[[#This Row],[UUID]],Planilha2!$A:$A,Planilha2!H:H,"") -> 0 | AP7: =_xlfn.XLOOKUP(Tabela5[[#This Row],[UUID]],Planilha2!$A:$A,Planilha2!I:I,"") -> 0 | AQ7: =_xlfn.XLOOKUP(Tabela5[[#This Row],[UUID]],Planilha2!$A:$A,Planilha2!J:J,"") -> 0 | AR7: =_xlfn.XLOOKUP(Tabela5[[#This Row],[UUID]],Planilha2!$A:$A,Planilha2!K:K,"") -> 0 | AS7: =_xlfn.XLOOKUP(Tabela5[[#This Row],[UUID]],Planilha2!$A:$A,Planilha2!L:L,"") -> 0 | AT7: =_xlfn.XLOOKUP(Tabela5[[#This Row],[UUID]],Planilha2!$A:$A,Planilha2!M:M,"") -> 0 | AU7: =_xlfn.XLOOKUP(Tabela5[[#This Row],[UUID]],Planilha2!$A:$A,Planilha2!N:N,"") -> 1 | AV7: =_xlfn.XLOOKUP(Tabela5[[#This Row],[UUID]],Planilha2!$A:$A,Planilha2!O:O,"") -> 1
A8: COB-242936 | B8: Faturado | C8: 11212444 | D8: 8161375526 | E8: KAYC VITOR ASSIS OLIVEIRA | F8: FZ ILICURITIBA 9999 CENTRO Conceição do Jacuípe BA 44245-000 | G8: ADE-16795-N2Y0W7 | H8: 46082 | I8: 202603 | J8: 169.47028 | L8: 169.47 | N8: 90520426 | O8: 46101 | P8: 46111 | R8: 15 | S8: 2 - CPF | T8: Em aberto - Vencido | U8: Em aberto - Vencido | V8: E7XRQO7 | W8: 6 | X8: false | Y8: 6 | Z8: Em aberto - Vencido | AA8: ASSOCIAÇÃO BA ? L1 | AB8: 35.686.965/0001-64 - ALEXANDRIA TECH | AC8: Estimado | AE8: 1 a 30 dias | AF8: 85c2c47d-d065-4e4d-928b-e750b48be0b5 | AG8: 46115 | AH8: 1 a 30 dias | AI8: =_xlfn.XLOOKUP(Tabela5[[#This Row],[UUID]],Planilha2!$A:$A,Planilha2!B:B,"") -> 1 | AJ8: =_xlfn.XLOOKUP(Tabela5[[#This Row],[UUID]],Planilha2!$A:$A,Planilha2!C:C,"") -> 1 | AK8: =_xlfn.XLOOKUP(Tabela5[[#This Row],[UUID]],Planilha2!$A:$A,Planilha2!D:D,"") -> 1 | AL8: =_xlfn.XLOOKUP(Tabela5[[#This Row],[UUID]],Planilha2!$A:$A,Planilha2!E:E,"") -> 0 | AM8: =_xlfn.XLOOKUP(Tabela5[[#This Row],[UUID]],Planilha2!$A:$A,Planilha2!F:F,"") -> 1 | AN8: =_xlfn.XLOOKUP(Tabela5[[#This Row],[UUID]],Planilha2!$A:$A,Planilha2!G:G,"") -> 1 | AO8: =_xlfn.XLOOKUP(Tabela5[[#This Row],[UUID]],Planilha2!$A:$A,Planilha2!H:H,"") -> 0 | AP8: =_xlfn.XLOOKUP(Tabela5[[#This Row],[UUID]],Planilha2!$A:$A,Planilha2!I:I,"") -> 0 | AQ8: =_xlfn.XLOOKUP(Tabela5[[#This Row],[UUID]],Planilha2!$A:$A,Planilha2!J:J,"") -> 0 | AR8: =_xlfn.XLOOKUP(Tabela5[[#This Row],[UUID]],Planilha2!$A:$A,Planilha2!K:K,"") -> 0 | AS8: =_xlfn.XLOOKUP(Tabela5[[#This Row],[UUID]],Planilha2!$A:$A,Planilha2!L:L,"") -> 0 | AT8: =_xlfn.XLOOKUP(Tabela5[[#This Row],[UUID]],Planilha2!$A:$A,Planilha2!M:M,"") -> 0 | AU8: =_xlfn.XLOOKUP(Tabela5[[#This Row],[UUID]],Planilha2!$A:$A,Planilha2!N:N,"") -> 1 | AV8: =_xlfn.XLOOKUP(Tabela5[[#This Row],[UUID]],Planilha2!$A:$A,Planilha2!O:O,"") -> 1
A9: COB-242926 | B9: Faturado | C9: 30243027 | D9: 95303383504 | E9: EVANILDA DE SOUZA SILVA SANTOS | F9: RUA AUTA LEITE OLIVEIRA 774 DO TANQUE Brumado BA 46100-000 | G9: ADE-16762-W4C4Y0 | H9: 46082 | I9: 202603 | J9: 187.27178 | L9: 187.27 | N9: 90520228 | O9: 46101 | P9: 46111 | R9: 15 | S9: 2 - CPF | T9: Em aberto - Vencido | U9: Em aberto - Vencido | V9: 05J946B | Y9: 6 | Z9: NA | AA9: ASSOCIAÇÃO BA ? L1 | AB9: 35.686.965/0001-64 - ALEXANDRIA TECH | AC9: Estimado | AE9: 1 a 30 dias | AF9: 7102abfa-f467-4498-9224-b177677008f0 | AG9: 46111 | AH9: 1 a 30 dias | AI9: =_xlfn.XLOOKUP(Tabela5[[#This Row],[UUID]],Planilha2!$A:$A,Planilha2!B:B,"") -> 1 | AJ9: =_xlfn.XLOOKUP(Tabela5[[#This Row],[UUID]],Planilha2!$A:$A,Planilha2!C:C,"") -> 1 | AK9: =_xlfn.XLOOKUP(Tabela5[[#This Row],[UUID]],Planilha2!$A:$A,Planilha2!D:D,"") -> 6 | AL9: =_xlfn.XLOOKUP(Tabela5[[#This Row],[UUID]],Planilha2!$A:$A,Planilha2!E:E,"") -> 0 | AM9: =_xlfn.XLOOKUP(Tabela5[[#This Row],[UUID]],Planilha2!$A:$A,Planilha2!F:F,"") -> 1 | AN9: =_xlfn.XLOOKUP(Tabela5[[#This Row],[UUID]],Planilha2!$A:$A,Planilha2!G:G,"") -> 1 | AO9: =_xlfn.XLOOKUP(Tabela5[[#This Row],[UUID]],Planilha2!$A:$A,Planilha2!H:H,"") -> 1 | AP9: =_xlfn.XLOOKUP(Tabela5[[#This Row],[UUID]],Planilha2!$A:$A,Planilha2!I:I,"") -> 0 | AQ9: =_xlfn.XLOOKUP(Tabela5[[#This Row],[UUID]],Planilha2!$A:$A,Planilha2!J:J,"") -> 0 | AR9: =_xlfn.XLOOKUP(Tabela5[[#This Row],[UUID]],Planilha2!$A:$A,Planilha2!K:K,"") -> 0 | AS9: =_xlfn.XLOOKUP(Tabela5[[#This Row],[UUID]],Planilha2!$A:$A,Planilha2!L:L,"") -> 0 | AT9: =_xlfn.XLOOKUP(Tabela5[[#This Row],[UUID]],Planilha2!$A:$A,Planilha2!M:M,"") -> 1 | AU9: =_xlfn.XLOOKUP(Tabela5[[#This Row],[UUID]],Planilha2!$A:$A,Planilha2!N:N,"") -> 1 | AV9: =_xlfn.XLOOKUP(Tabela5[[#This Row],[UUID]],Planilha2!$A:$A,Planilha2!O:O,"") -> 1
A10: COB-242920 | B10: Faturado | C10: 6538183 | D10: 40407594 | E10: MARIA JOSE FERREIRA DE OLIVEIRA | F10: RUA PADRE MANOEL NOBREGA 32 CRUZEIRO Vitória da Conquista BA 45000-000 | G10: ADE-16632-P5Q3G8 | H10: 46082 | I10: 202603 | J10: 143.59402 | L10: 143.59 | N10: 90520276 | O10: 46101 | P10: 46111 | R10: 15 | S10: 2 - CPF | T10: Em aberto - Vencido | U10: Em aberto - Vencido | V10: D9506SY | W10: 6 | X10: false | Y10: 6 | Z10: Em aberto - Vencido | AA10: ASSOCIAÇÃO BA ? L1 | AB10: 35.686.965/0001-64 - ALEXANDRIA TECH | AC10: Estimado | AE10: 1 a 30 dias | AF10: 47b1bf63-a080-4de2-ae40-d66a39bb05f1 | AG10: 46115 | AH10: 1 a 30 dias | AI10: =_xlfn.XLOOKUP(Tabela5[[#This Row],[UUID]],Planilha2!$A:$A,Planilha2!B:B,"") -> 1 | AJ10: =_xlfn.XLOOKUP(Tabela5[[#This Row],[UUID]],Planilha2!$A:$A,Planilha2!C:C,"") -> 1 | AK10: =_xlfn.XLOOKUP(Tabela5[[#This Row],[UUID]],Planilha2!$A:$A,Planilha2!D:D,"") -> 1 | AL10: =_xlfn.XLOOKUP(Tabela5[[#This Row],[UUID]],Planilha2!$A:$A,Planilha2!E:E,"") -> 0 | AM10: =_xlfn.XLOOKUP(Tabela5[[#This Row],[UUID]],Planilha2!$A:$A,Planilha2!F:F,"") -> 1 | AN10: =_xlfn.XLOOKUP(Tabela5[[#This Row],[UUID]],Planilha2!$A:$A,Planilha2!G:G,"") -> 1 | AO10: =_xlfn.XLOOKUP(Tabela5[[#This Row],[UUID]],Planilha2!$A:$A,Planilha2!H:H,"") -> 0 | AP10: =_xlfn.XLOOKUP(Tabela5[[#This Row],[UUID]],Planilha2!$A:$A,Planilha2!I:I,"") -> 0 | AQ10: =_xlfn.XLOOKUP(Tabela5[[#This Row],[UUID]],Planilha2!$A:$A,Planilha2!J:J,"") -> 0 | AR10: =_xlfn.XLOOKUP(Tabela5[[#This Row],[UUID]],Planilha2!$A:$A,Planilha2!K:K,"") -> 0 | AS10: =_xlfn.XLOOKUP(Tabela5[[#This Row],[UUID]],Planilha2!$A:$A,Planilha2!L:L,"") -> 0 | AT10: =_xlfn.XLOOKUP(Tabela5[[#This Row],[UUID]],Planilha2!$A:$A,Planilha2!M:M,"") -> 0 | AU10: =_xlfn.XLOOKUP(Tabela5[[#This Row],[UUID]],Planilha2!$A:$A,Planilha2!N:N,"") -> 1 | AV10: =_xlfn.XLOOKUP(Tabela5[[#This Row],[UUID]],Planilha2!$A:$A,Planilha2!O:O,"") -> 1
A11: COB-242908 | B11: Faturado | C11: 10922377 | D11: 326740589 | E11: CLAUDIVANE MIRANDA DA SILVA | F11: RUA DIRETA DA MANGABEIRA 69 C Cajazeiras VIII Salvador BA 41338-710 | G11: ADE-16529-W6Y2L0 | H11: 46082 | I11: 202603 | J11: 311.17022 | L11: 311.17 | N11: 90520366 | O11: 46101 | P11: 46111 | R11: 15 | S11: 2 - CPF | T11: Em aberto - Vencido | U11: Em aberto - Vencido | V11: PRADFKG | W11: 6 | X11: false | Y11: 6 | Z11: Em aberto - Vencido | AA11: ASSOCIAÇÃO BA ? L1 | AB11: 35.686.965/0001-64 - ALEXANDRIA TECH | AC11: Estimado | AE11: 1 a 30 dias | AF11: e0013a76-c338-4256-bfb2-f914966e5c27 | AG11: 46115 | AH11: 1 a 30 dias | AI11: =_xlfn.XLOOKUP(Tabela5[[#This Row],[UUID]],Planilha2!$A:$A,Planilha2!B:B,"") -> 1 | AJ11: =_xlfn.XLOOKUP(Tabela5[[#This Row],[UUID]],Planilha2!$A:$A,Planilha2!C:C,"") -> 1 | AK11: =_xlfn.XLOOKUP(Tabela5[[#This Row],[UUID]],Planilha2!$A:$A,Planilha2!D:D,"") -> 12 | AL11: =_xlfn.XLOOKUP(Tabela5[[#This Row],[UUID]],Planilha2!$A:$A,Planilha2!E:E,"") -> 0 | AM11: =_xlfn.XLOOKUP(Tabela5[[#This Row],[UUID]],Planilha2!$A:$A,Planilha2!F:F,"") -> 1 | AN11: =_xlfn.XLOOKUP(Tabela5[[#This Row],[UUID]],Planilha2!$A:$A,Planilha2!G:G,"") -> 1 | AO11: =_xlfn.XLOOKUP(Tabela5[[#This Row],[UUID]],Planilha2!$A:$A,Planilha2!H:H,"") -> 0 | AP11: =_xlfn.XLOOKUP(Tabela5[[#This Row],[UUID]],Planilha2!$A:$A,Planilha2!I:I,"") -> 0 | AQ11: =_xlfn.XLOOKUP(Tabela5[[#This Row],[UUID]],Planilha2!$A:$A,Planilha2!J:J,"") -> 0 | AR11: =_xlfn.XLOOKUP(Tabela5[[#This Row],[UUID]],Planilha2!$A:$A,Planilha2!K:K,"") -> 0 | AS11: =_xlfn.XLOOKUP(Tabela5[[#This Row],[UUID]],Planilha2!$A:$A,Planilha2!L:L,"") -> 0 | AT11: =_xlfn.XLOOKUP(Tabela5[[#This Row],[UUID]],Planilha2!$A:$A,Planilha2!M:M,"") -> 0 | AU11: =_xlfn.XLOOKUP(Tabela5[[#This Row],[UUID]],Planilha2!$A:$A,Planilha2!N:N,"") -> 1 | AV11: =_xlfn.XLOOKUP(Tabela5[[#This Row],[UUID]],Planilha2!$A:$A,Planilha2!O:O,"") -> 1
A12: COB-125624 | B12: Faturado | C12: 74420895 | D12: 18308585809 | E12: VAGNER MAURO ALCARAZ | F12: RUA CARLOTA MARCIO 475 11677-000 MASSAGUACU / CARAGUATATUBA - SP | G12: ADE-12297-B5R6H6 | H12: 45839 | I12: 202507 | J12: 580.94785 | L12: 580.95 | N12: 90364329 | O12: 45916 | P12: 45926 | R12: 200 | S12: 2 - CPF | T12: Em aberto - Vencido | U12: Em aberto - Vencido | V12: 9QGZO0A | W12: 6 | X12: false | Y12: 6 | Z12: Em aberto - Vencido | AA12: ASSOCIAÇÃO SP-L3 | AB12: 35.686.965/0001-64 - ALEXANDRIA TECH | AE12: 171 a 450 dias | AF12: 159cfc1a-ef8c-4fcc-8ac4-999baf6c1e2a | AG12: 45965 | AH12: Maior que 90 | AI12: =_xlfn.XLOOKUP(Tabela5[[#This Row],[UUID]],Planilha2!$A:$A,Planilha2!B:B,"") -> 0 | AJ12: =_xlfn.XLOOKUP(Tabela5[[#This Row],[UUID]],Planilha2!$A:$A,Planilha2!C:C,"") -> 0 | AK12: =_xlfn.XLOOKUP(Tabela5[[#This Row],[UUID]],Planilha2!$A:$A,Planilha2!D:D,"") -> 0 | AL12: =_xlfn.XLOOKUP(Tabela5[[#This Row],[UUID]],Planilha2!$A:$A,Planilha2!E:E,"") -> 5 | AM12: =_xlfn.XLOOKUP(Tabela5[[#This Row],[UUID]],Planilha2!$A:$A,Planilha2!F:F,"") -> 0 | AN12: =_xlfn.XLOOKUP(Tabela5[[#This Row],[UUID]],Planilha2!$A:$A,Planilha2!G:G,"") -> 0 | AO12: =_xlfn.XLOOKUP(Tabela5[[#This Row],[UUID]],Planilha2!$A:$A,Planilha2!H:H,"") -> 0 | AP12: =_xlfn.XLOOKUP(Tabela5[[#This Row],[UUID]],Planilha2!$A:$A,Planilha2!I:I,"") -> 0 | AQ12: =_xlfn.XLOOKUP(Tabela5[[#This Row],[UUID]],Planilha2!$A:$A,Planilha2!J:J,"") -> 0 | AR12: =_xlfn.XLOOKUP(Tabela5[[#This Row],[UUID]],Planilha2!$A:$A,Planilha2!K:K,"") -> 0 | AS12: =_xlfn.XLOOKUP(Tabela5[[#This Row],[UUID]],Planilha2!$A:$A,Planilha2!L:L,"") -> 0 | AT12: =_xlfn.XLOOKUP(Tabela5[[#This Row],[UUID]],Planilha2!$A:$A,Planilha2!M:M,"") -> 0 | AU12: =_xlfn.XLOOKUP(Tabela5[[#This Row],[UUID]],Planilha2!$A:$A,Planilha2!N:N,"") -> 0 | AV12: =_xlfn.XLOOKUP(Tabela5[[#This Row],[UUID]],Planilha2!$A:$A,Planilha2!O:O,"") -> 0
A13: COB-242907 | B13: Faturado | C13: 4989707 | D13: 13347454553 | E13: JOSE SANTANA FRANCA | F13: Rua Opatciana da Silva Oliveira 132 AP: 102 CJ Rodrigo Salvador BROTAS Salvador BA 40276-070 | G13: ADE-16525-J2C8R6 | H13: 46082 | I13: 202603 | J13: 124.6105 | L13: 124.61 | N13: 90520316 | O13: 46101 | P13: 46111 | R13: 15 | S13: 2 - CPF | T13: Em aberto - Vencido | U13: Em aberto - Vencido | V13: BQSCN0K | W13: 6 | X13: false | Y13: 6 | Z13: Em aberto - Vencido | AA13: ASSOCIAÇÃO BA ? L1 | AB13: 35.686.965/0001-64 - ALEXANDRIA TECH | AC13: Estimado | AE13: 1 a 30 dias | AF13: 622cd132-8f40-44ea-93fd-965ed0144832 | AG13: 46115 | AH13: 1 a 30 dias | AI13: =_xlfn.XLOOKUP(Tabela5[[#This Row],[UUID]],Planilha2!$A:$A,Planilha2!B:B,"") -> 1 | AJ13: =_xlfn.XLOOKUP(Tabela5[[#This Row],[UUID]],Planilha2!$A:$A,Planilha2!C:C,"") -> 1 | AK13: =_xlfn.XLOOKUP(Tabela5[[#This Row],[UUID]],Planilha2!$A:$A,Planilha2!D:D,"") -> 1 | AL13: =_xlfn.XLOOKUP(Tabela5[[#This Row],[UUID]],Planilha2!$A:$A,Planilha2!E:E,"") -> 0 | AM13: =_xlfn.XLOOKUP(Tabela5[[#This Row],[UUID]],Planilha2!$A:$A,Planilha2!F:F,"") -> 1 | AN13: =_xlfn.XLOOKUP(Tabela5[[#This Row],[UUID]],Planilha2!$A:$A,Planilha2!G:G,"") -> 1 | AO13: =_xlfn.XLOOKUP(Tabela5[[#This Row],[UUID]],Planilha2!$A:$A,Planilha2!H:H,"") -> 0 | AP13: =_xlfn.XLOOKUP(Tabela5[[#This Row],[UUID]],Planilha2!$A:$A,Planilha2!I:I,"") -> 0 | AQ13: =_xlfn.XLOOKUP(Tabela5[[#This Row],[UUID]],Planilha2!$A:$A,Planilha2!J:J,"") -> 0 | AR13: =_xlfn.XLOOKUP(Tabela5[[#This Row],[UUID]],Planilha2!$A:$A,Planilha2!K:K,"") -> 0 | AS13: =_xlfn.XLOOKUP(Tabela5[[#This Row],[UUID]],Planilha2!$A:$A,Planilha2!L:L,"") -> 0 | AT13: =_xlfn.XLOOKUP(Tabela5[[#This Row],[UUID]],Planilha2!$A:$A,Planilha2!M:M,"") -> 0 | AU13: =_xlfn.XLOOKUP(Tabela5[[#This Row],[UUID]],Planilha2!$A:$A,Planilha2!N:N,"") -> 1 | AV13: =_xlfn.XLOOKUP(Tabela5[[#This Row],[UUID]],Planilha2!$A:$A,Planilha2!O:O,"") -> 1
A14: COB-242906 | B14: Faturado | C14: 1491079 | D14: 4746887551 | E14: ANA CORDEIRO VICENTE | F14: RUA ANTONIO OLIMP DA SILVA 136 JUCA ROSA Eunápolis BA 45833-999 | G14: ADE-16509-Z2N3T3 | H14: 46082 | I14: 202603 | J14: 168.04616 | L14: 168.05 | N14: 90520484 | O14: 46101 | P14: 46111 | R14: 15 | S14: 2 - CPF | T14: Em aberto - Vencido | U14: Em aberto - Vencido | V14: XQOC28O | W14: 6 | X14: false | Y14: 6 | Z14: Em aberto - Vencido | AA14: ASSOCIAÇÃO BA ? L1 | AB14: 35.686.965/0001-64 - ALEXANDRIA TECH | AC14: Estimado | AE14: 1 a 30 dias | AF14: 639dd04c-82dd-45f9-a862-8da0cb96b2c1 | AG14: 46115 | AH14: 1 a 30 dias | AI14: =_xlfn.XLOOKUP(Tabela5[[#This Row],[UUID]],Planilha2!$A:$A,Planilha2!B:B,"") -> 1 | AJ14: =_xlfn.XLOOKUP(Tabela5[[#This Row],[UUID]],Planilha2!$A:$A,Planilha2!C:C,"") -> 1 | AK14: =_xlfn.XLOOKUP(Tabela5[[#This Row],[UUID]],Planilha2!$A:$A,Planilha2!D:D,"") -> 1 | AL14: =_xlfn.XLOOKUP(Tabela5[[#This Row],[UUID]],Planilha2!$A:$A,Planilha2!E:E,"") -> 0 | AM14: =_xlfn.XLOOKUP(Tabela5[[#This Row],[UUID]],Planilha2!$A:$A,Planilha2!F:F,"") -> 1 | AN14: =_xlfn.XLOOKUP(Tabela5[[#This Row],[UUID]],Planilha2!$A:$A,Planilha2!G:G,"") -> 1 | AO14: =_xlfn.XLOOKUP(Tabela5[[#This Row],[UUID]],Planilha2!$A:$A,Planilha2!H:H,"") -> 0 | AP14: =_xlfn.XLOOKUP(Tabela5[[#This Row],[UUID]],Planilha2!$A:$A,Planilha2!I:I,"") -> 0 | AQ14: =_xlfn.XLOOKUP(Tabela5[[#This Row],[UUID]],Planilha2!$A:$A,Planilha2!J:J,"") -> 0 | AR14: =_xlfn.XLOOKUP(Tabela5[[#This Row],[UUID]],Planilha2!$A:$A,Planilha2!K:K,"") -> 0 | AS14: =_xlfn.XLOOKUP(Tabela5[[#This Row],[UUID]],Planilha2!$A:$A,Planilha2!L:L,"") -> 0 | AT14: =_xlfn.XLOOKUP(Tabela5[[#This Row],[UUID]],Planilha2!$A:$A,Planilha2!M:M,"") -> 0 | AU14: =_xlfn.XLOOKUP(Tabela5[[#This Row],[UUID]],Planilha2!$A:$A,Planilha2!N:N,"") -> 1 | AV14: =_xlfn.XLOOKUP(Tabela5[[#This Row],[UUID]],Planilha2!$A:$A,Planilha2!O:O,"") -> 1
A15: COB-242902 | B15: Faturado | C15: 759988 | D15: 18857167534 | E15: SEBASTIAO CASTRO DA SILVA | F15: CA 22 2 B GLEBA E/CAMACARI Camaçari BA 42849-999 | G15: ADE-16502-H5B5N2 | H15: 46082 | I15: 202603 | J15: 178.72706 | L15: 178.73 | N15: 90520303 | O15: 46101 | P15: 46111 | R15: 15 | S15: 2 - CPF | T15: Em aberto - Vencido | U15: Em aberto - Vencido | V15: TRZA0UH | W15: 6 | X15: false | Y15: 6 | Z15: Em aberto - Vencido | AA15: ASSOCIAÇÃO BA ? L1 | AB15: 35.686.965/0001-64 - ALEXANDRIA TECH | AC15: Estimado | AE15: 1 a 30 dias | AF15: 896e934c-975f-47a0-8f55-a7d2e63dd813 | AG15: 46115 | AH15: 1 a 30 dias | AI15: =_xlfn.XLOOKUP(Tabela5[[#This Row],[UUID]],Planilha2!$A:$A,Planilha2!B:B,"") -> 1 | AJ15: =_xlfn.XLOOKUP(Tabela5[[#This Row],[UUID]],Planilha2!$A:$A,Planilha2!C:C,"") -> 1 | AK15: =_xlfn.XLOOKUP(Tabela5[[#This Row],[UUID]],Planilha2!$A:$A,Planilha2!D:D,"") -> 11 | AL15: =_xlfn.XLOOKUP(Tabela5[[#This Row],[UUID]],Planilha2!$A:$A,Planilha2!E:E,"") -> 0 | AM15: =_xlfn.XLOOKUP(Tabela5[[#This Row],[UUID]],Planilha2!$A:$A,Planilha2!F:F,"") -> 1 | AN15: =_xlfn.XLOOKUP(Tabela5[[#This Row],[UUID]],Planilha2!$A:$A,Planilha2!G:G,"") -> 1 | AO15: =_xlfn.XLOOKUP(Tabela5[[#This Row],[UUID]],Planilha2!$A:$A,Planilha2!H:H,"") -> 0 | AP15: =_xlfn.XLOOKUP(Tabela5[[#This Row],[UUID]],Planilha2!$A:$A,Planilha2!I:I,"") -> 0 | AQ15: =_xlfn.XLOOKUP(Tabela5[[#This Row],[UUID]],Planilha2!$A:$A,Planilha2!J:J,"") -> 0 | AR15: =_xlfn.XLOOKUP(Tabela5[[#This Row],[UUID]],Planilha2!$A:$A,Planilha2!K:K,"") -> 0 | AS15: =_xlfn.XLOOKUP(Tabela5[[#This Row],[UUID]],Planilha2!$A:$A,Planilha2!L:L,"") -> 0 | AT15: =_xlfn.XLOOKUP(Tabela5[[#This Row],[UUID]],Planilha2!$A:$A,Planilha2!M:M,"") -> 0 | AU15: =_xlfn.XLOOKUP(Tabela5[[#This Row],[UUID]],Planilha2!$A:$A,Planilha2!N:N,"") -> 1 | AV15: =_xlfn.XLOOKUP(Tabela5[[#This Row],[UUID]],Planilha2!$A:$A,Planilha2!O:O,"") -> 1
A16: COB-242901 | B16: Faturado | C16: 4771655 | D16: 46859071591 | E16: SANDOVAL AMARAL DOS SANTOS | F16: VIA COLETADORA B 1300 CD Res Portal do Vale Bl 03 Ap 303 CAJAZEIRAS Salvador BA 41345-100 | G16: ADE-16500-Q3B1N7 | H16: 46082 | I16: 202603 | J16: 149.5326 | L16: 149.53 | N16: 90520463 | O16: 46101 | P16: 46111 | R16: 15 | S16: 2 - CPF | T16: Em aberto - Vencido | U16: Em aberto - Vencido | V16: 11FTOV0 | W16: 6 | X16: false | Y16: 6 | Z16: Em aberto - Vencido | AA16: ASSOCIAÇÃO BA ? L1 | AB16: 35.686.965/0001-64 - ALEXANDRIA TECH | AC16: Estimado | AE16: 1 a 30 dias | AF16: f5817f41-7a5d-452f-ba2b-648168cd5e6b | AG16: 46115 | AH16: 1 a 30 dias | AI16: =_xlfn.XLOOKUP(Tabela5[[#This Row],[UUID]],Planilha2!$A:$A,Planilha2!B:B,"") -> 1 | AJ16: =_xlfn.XLOOKUP(Tabela5[[#This Row],[UUID]],Planilha2!$A:$A,Planilha2!C:C,"") -> 1 | AK16: =_xlfn.XLOOKUP(Tabela5[[#This Row],[UUID]],Planilha2!$A:$A,Planilha2!D:D,"") -> 1 | AL16: =_xlfn.XLOOKUP(Tabela5[[#This Row],[UUID]],Planilha2!$A:$A,Planilha2!E:E,"") -> 0 | AM16: =_xlfn.XLOOKUP(Tabela5[[#This Row],[UUID]],Planilha2!$A:$A,Planilha2!F:F,"") -> 1 | AN16: =_xlfn.XLOOKUP(Tabela5[[#This Row],[UUID]],Planilha2!$A:$A,Planilha2!G:G,"") -> 1 | AO16: =_xlfn.XLOOKUP(Tabela5[[#This Row],[UUID]],Planilha2!$A:$A,Planilha2!H:H,"") -> 0 | AP16: =_xlfn.XLOOKUP(Tabela5[[#This Row],[UUID]],Planilha2!$A:$A,Planilha2!I:I,"") -> 0 | AQ16: =_xlfn.XLOOKUP(Tabela5[[#This Row],[UUID]],Planilha2!$A:$A,Planilha2!J:J,"") -> 0 | AR16: =_xlfn.XLOOKUP(Tabela5[[#This Row],[UUID]],Planilha2!$A:$A,Planilha2!K:K,"") -> 0 | AS16: =_xlfn.XLOOKUP(Tabela5[[#This Row],[UUID]],Planilha2!$A:$A,Planilha2!L:L,"") -> 0 | AT16: =_xlfn.XLOOKUP(Tabela5[[#This Row],[UUID]],Planilha2!$A:$A,Planilha2!M:M,"") -> 0 | AU16: =_xlfn.XLOOKUP(Tabela5[[#This Row],[UUID]],Planilha2!$A:$A,Planilha2!N:N,"") -> 1 | AV16: =_xlfn.XLOOKUP(Tabela5[[#This Row],[UUID]],Planilha2!$A:$A,Planilha2!O:O,"") -> 1
A17: COB-242897 | B17: Faturado | C17: 70250212 | D17: 86411440565 | E17: QUEVENI DEIRON DOS SANTOS | F17: RUA ACU DA TORRE 59 A Praia do Forte Mata de São João BA 48287-000 | G17: ADE-16492-V1J0S7 | H17: 46082 | I17: 202603 | J17: 3155.1379 | L17: 3155.14 | N17: 90520438 | O17: 46101 | P17: 46111 | R17: 15 | S17: 2 - CPF | T17: Em aberto - Vencido | U17: Em aberto - Vencido | V17: RFD99E0 | Y17: 6 | Z17: NA | AA17: ASSOCIAÇÃO BA ? L1 | AB17: 35.686.965/0001-64 - ALEXANDRIA TECH | AC17: Estimado | AE17: 1 a 30 dias | AF17: ca7705bf-29a8-46a6-b1f1-23e3ba1bef05 | AG17: 46115 | AH17: 1 a 30 dias | AI17: =_xlfn.XLOOKUP(Tabela5[[#This Row],[UUID]],Planilha2!$A:$A,Planilha2!B:B,"") -> 1 | AJ17: =_xlfn.XLOOKUP(Tabela5[[#This Row],[UUID]],Planilha2!$A:$A,Planilha2!C:C,"") -> 1 | AK17: =_xlfn.XLOOKUP(Tabela5[[#This Row],[UUID]],Planilha2!$A:$A,Planilha2!D:D,"") -> 10 | AL17: =_xlfn.XLOOKUP(Tabela5[[#This Row],[UUID]],Planilha2!$A:$A,Planilha2!E:E,"") -> 0 | AM17: =_xlfn.XLOOKUP(Tabela5[[#This Row],[UUID]],Planilha2!$A:$A,Planilha2!F:F,"") -> 1 | AN17: =_xlfn.XLOOKUP(Tabela5[[#This Row],[UUID]],Planilha2!$A:$A,Planilha2!G:G,"") -> 1 | AO17: =_xlfn.XLOOKUP(Tabela5[[#This Row],[UUID]],Planilha2!$A:$A,Planilha2!H:H,"") -> 0 | AP17: =_xlfn.XLOOKUP(Tabela5[[#This Row],[UUID]],Planilha2!$A:$A,Planilha2!I:I,"") -> 0 | AQ17: =_xlfn.XLOOKUP(Tabela5[[#This Row],[UUID]],Planilha2!$A:$A,Planilha2!J:J,"") -> 0 | AR17: =_xlfn.XLOOKUP(Tabela5[[#This Row],[UUID]],Planilha2!$A:$A,Planilha2!K:K,"") -> 0 | AS17: =_xlfn.XLOOKUP(Tabela5[[#This Row],[UUID]],Planilha2!$A:$A,Planilha2!L:L,"") -> 0 | AT17: =_xlfn.XLOOKUP(Tabela5[[#This Row],[UUID]],Planilha2!$A:$A,Planilha2!M:M,"") -> 0 | AU17: =_xlfn.XLOOKUP(Tabela5[[#This Row],[UUID]],Planilha2!$A:$A,Planilha2!N:N,"") -> 1 | AV17: =_xlfn.XLOOKUP(Tabela5[[#This Row],[UUID]],Planilha2!$A:$A,Planilha2!O:O,"") -> 1
A18: COB-242891 | B18: Faturado | C18: 1475211 | D18: 35140015889 | E18: UILES OLIVEIRA MEIRA | F18: RUA SAO JUDAS TADEU 19 Rosa Neto Eunápolis BA 45823-210 | G18: ADE-16435-R8F8P5 | H18: 46082 | I18: 202603 | J18: 219.31448 | L18: 219.31 | N18: 90520528 | O18: 46101 | P18: 46111 | R18: 15 | S18: 2 - CPF | T18: Em aberto - Vencido | U18: Em aberto - Vencido | V18: 3Z3BNU1 | W18: 6 | X18: false | Y18: 6 | Z18: Em aberto - Vencido | AA18: ASSOCIAÇÃO BA ? L1 | AB18: 35.686.965/0001-64 - ALEXANDRIA TECH | AC18: Estimado | AE18: 1 a 30 dias | AF18: 58f53212-2251-4d6a-ab70-f3b3b8bf414f | AG18: 46115 | AH18: 1 a 30 dias | AI18: =_xlfn.XLOOKUP(Tabela5[[#This Row],[UUID]],Planilha2!$A:$A,Planilha2!B:B,"") -> 1 | AJ18: =_xlfn.XLOOKUP(Tabela5[[#This Row],[UUID]],Planilha2!$A:$A,Planilha2!C:C,"") -> 1 | AK18: =_xlfn.XLOOKUP(Tabela5[[#This Row],[UUID]],Planilha2!$A:$A,Planilha2!D:D,"") -> 1 | AL18: =_xlfn.XLOOKUP(Tabela5[[#This Row],[UUID]],Planilha2!$A:$A,Planilha2!E:E,"") -> 0 | AM18: =_xlfn.XLOOKUP(Tabela5[[#This Row],[UUID]],Planilha2!$A:$A,Planilha2!F:F,"") -> 1 | AN18: =_xlfn.XLOOKUP(Tabela5[[#This Row],[UUID]],Planilha2!$A:$A,Planilha2!G:G,"") -> 1 | AO18: =_xlfn.XLOOKUP(Tabela5[[#This Row],[UUID]],Planilha2!$A:$A,Planilha2!H:H,"") -> 0 | AP18: =_xlfn.XLOOKUP(Tabela5[[#This Row],[UUID]],Planilha2!$A:$A,Planilha2!I:I,"") -> 0 | AQ18: =_xlfn.XLOOKUP(Tabela5[[#This Row],[UUID]],Planilha2!$A:$A,Planilha2!J:J,"") -> 0 | AR18: =_xlfn.XLOOKUP(Tabela5[[#This Row],[UUID]],Planilha2!$A:$A,Planilha2!K:K,"") -> 0 | AS18: =_xlfn.XLOOKUP(Tabela5[[#This Row],[UUID]],Planilha2!$A:$A,Planilha2!L:L,"") -> 0 | AT18: =_xlfn.XLOOKUP(Tabela5[[#This Row],[UUID]],Planilha2!$A:$A,Planilha2!M:M,"") -> 0 | AU18: =_xlfn.XLOOKUP(Tabela5[[#This Row],[UUID]],Planilha2!$A:$A,Planilha2!N:N,"") -> 1 | AV18: =_xlfn.XLOOKUP(Tabela5[[#This Row],[UUID]],Planilha2!$A:$A,Planilha2!O:O,"") -> 1
A19: COB-242892 | B19: Faturado | C19: 763229 | D19: 33490902572 | E19: ALCIR GOMES SANTOS | F19: CA D 08 19 NOVO HORIZONTE Camaçari BA 42849-999 | G19: ADE-16434-J1P7Q2 | H19: 46082 | I19: 202603 | J19: 128.1708 | L19: 128.17 | N19: 90520516 | O19: 46101 | P19: 46111 | R19: 15 | S19: 2 - CPF | T19: Em aberto - Vencido | U19: Em aberto - Vencido | V19: P3OEP8P | W19: 6 | X19: false | Y19: 6 | Z19: Em aberto - Vencido | AA19: ASSOCIAÇÃO BA ? L1 | AB19: 35.686.965/0001-64 - ALEXANDRIA TECH | AC19: Estimado | AE19: 1 a 30 dias | AF19: 1e6ffd93-9562-48f3-8e39-27de4349d95e | AG19: 46115 | AH19: 1 a 30 dias | AI19: =_xlfn.XLOOKUP(Tabela5[[#This Row],[UUID]],Planilha2!$A:$A,Planilha2!B:B,"") -> 1 | AJ19: =_xlfn.XLOOKUP(Tabela5[[#This Row],[UUID]],Planilha2!$A:$A,Planilha2!C:C,"") -> 1 | AK19: =_xlfn.XLOOKUP(Tabela5[[#This Row],[UUID]],Planilha2!$A:$A,Planilha2!D:D,"") -> 1 | AL19: =_xlfn.XLOOKUP(Tabela5[[#This Row],[UUID]],Planilha2!$A:$A,Planilha2!E:E,"") -> 0 | AM19: =_xlfn.XLOOKUP(Tabela5[[#This Row],[UUID]],Planilha2!$A:$A,Planilha2!F:F,"") -> 1 | AN19: =_xlfn.XLOOKUP(Tabela5[[#This Row],[UUID]],Planilha2!$A:$A,Planilha2!G:G,"") -> 1 | AO19: =_xlfn.XLOOKUP(Tabela5[[#This Row],[UUID]],Planilha2!$A:$A,Planilha2!H:H,"") -> 0 | AP19: =_xlfn.XLOOKUP(Tabela5[[#This Row],[UUID]],Planilha2!$A:$A,Planilha2!I:I,"") -> 0 | AQ19: =_xlfn.XLOOKUP(Tabela5[[#This Row],[UUID]],Planilha2!$A:$A,Planilha2!J:J,"") -> 0 | AR19: =_xlfn.XLOOKUP(Tabela5[[#This Row],[UUID]],Planilha2!$A:$A,Planilha2!K:K,"") -> 0 | AS19: =_xlfn.XLOOKUP(Tabela5[[#This Row],[UUID]],Planilha2!$A:$A,Planilha2!L:L,"") -> 0 | AT19: =_xlfn.XLOOKUP(Tabela5[[#This Row],[UUID]],Planilha2!$A:$A,Planilha2!M:M,"") -> 0 | AU19: =_xlfn.XLOOKUP(Tabela5[[#This Row],[UUID]],Planilha2!$A:$A,Planilha2!N:N,"") -> 1 | AV19: =_xlfn.XLOOKUP(Tabela5[[#This Row],[UUID]],Planilha2!$A:$A,Planilha2!O:O,"") -> 1
A20: COB-242888 | B20: Faturado | C20: 4262924 | D20: 7015471540 | E20: TAMISSON SILVA MELO | F20: RUA DO BALNEARIO 110 ED AMARALINA PREDIO DA LOTERICA ESPORTIV AMARALINA Salvador BA 41900-050 | G20: ADE-16431-Q3T8C6 | H20: 46082 | I20: 202603 | J20: 205.78534 | L20: 205.79 | N20: 90520389 | O20: 46101 | P20: 46111 | R20: 15 | S20: 2 - CPF | T20: Em aberto - Vencido | U20: Em aberto - Vencido | V20: 6KDR19A | W20: 6 | X20: false | Y20: 6 | Z20: Em aberto - Vencido | AA20: ASSOCIAÇÃO BA ? L1 | AB20: 35.686.965/0001-64 - ALEXANDRIA TECH | AC20: Estimado | AE20: 1 a 30 dias | AF20: 6d962e72-a894-45b6-83e0-43f20aecc3a2 | AG20: 46115 | AH20: 1 a 30 dias | AI20: =_xlfn.XLOOKUP(Tabela5[[#This Row],[UUID]],Planilha2!$A:$A,Planilha2!B:B,"") -> 1 | AJ20: =_xlfn.XLOOKUP(Tabela5[[#This Row],[UUID]],Planilha2!$A:$A,Planilha2!C:C,"") -> 1 | AK20: =_xlfn.XLOOKUP(Tabela5[[#This Row],[UUID]],Planilha2!$A:$A,Planilha2!D:D,"") -> 10 | AL20: =_xlfn.XLOOKUP(Tabela5[[#This Row],[UUID]],Planilha2!$A:$A,Planilha2!E:E,"") -> 0 | AM20: =_xlfn.XLOOKUP(Tabela5[[#This Row],[UUID]],Planilha2!$A:$A,Planilha2!F:F,"") -> 1 | AN20: =_xlfn.XLOOKUP(Tabela5[[#This Row],[UUID]],Planilha2!$A:$A,Planilha2!G:G,"") -> 1 | AO20: =_xlfn.XLOOKUP(Tabela5[[#This Row],[UUID]],Planilha2!$A:$A,Planilha2!H:H,"") -> 0 | AP20: =_xlfn.XLOOKUP(Tabela5[[#This Row],[UUID]],Planilha2!$A:$A,Planilha2!I:I,"") -> 0 | AQ20: =_xlfn.XLOOKUP(Tabela5[[#This Row],[UUID]],Planilha2!$A:$A,Planilha2!J:J,"") -> 0 | AR20: =_xlfn.XLOOKUP(Tabela5[[#This Row],[UUID]],Planilha2!$A:$A,Planilha2!K:K,"") -> 0 | AS20: =_xlfn.XLOOKUP(Tabela5[[#This Row],[UUID]],Planilha2!$A:$A,Planilha2!L:L,"") -> 0 | AT20: =_xlfn.XLOOKUP(Tabela5[[#This Row],[UUID]],Planilha2!$A:$A,Planilha2!M:M,"") -> 0 | AU20: =_xlfn.XLOOKUP(Tabela5[[#This Row],[UUID]],Planilha2!$A:$A,Planilha2!N:N,"") -> 1 | AV20: =_xlfn.XLOOKUP(Tabela5[[#This Row],[UUID]],Planilha2!$A:$A,Planilha2!O:O,"") -> 1
A21: COB-242548 | B21: Faturado | C21: 5293706 | D21: 2436169535 | E21: REGINA BARBARA SANTOS SILVA | F21: RUA BELA VISTA DO CABRAL 94 SALVADOR 94 Nazaré Salvador BA 40055-000 | G21: ADE-14206-P2S4H8 | H21: 46082 | I21: 202603 | J21: 508.41084 | L21: 508.41 | N21: 90520353 | O21: 46101 | P21: 46111 | R21: 15 | S21: 2 - CPF | T21: Em aberto - Vencido | U21: Em aberto - Vencido | V21: 4NHRTWD | W21: 6 | X21: false | Y21: 6 | Z21: Em aberto - Vencido | AA21: ASSOCIAÇÃO BA ? L1 | AB21: 35.686.965/0001-64 - ALEXANDRIA TECH | AC21: Estimado | AE21: 1 a 30 dias | AF21: 5123a75a-49f9-4223-b470-821f9e7bd3a7 | AG21: 46115 | AH21: 1 a 30 dias | AI21: =_xlfn.XLOOKUP(Tabela5[[#This Row],[UUID]],Planilha2!$A:$A,Planilha2!B:B,"") -> 1 | AJ21: =_xlfn.XLOOKUP(Tabela5[[#This Row],[UUID]],Planilha2!$A:$A,Planilha2!C:C,"") -> 1 | AK21: =_xlfn.XLOOKUP(Tabela5[[#This Row],[UUID]],Planilha2!$A:$A,Planilha2!D:D,"") -> 12 | AL21: =_xlfn.XLOOKUP(Tabela5[[#This Row],[UUID]],Planilha2!$A:$A,Planilha2!E:E,"") -> 0 | AM21: =_xlfn.XLOOKUP(Tabela5[[#This Row],[UUID]],Planilha2!$A:$A,Planilha2!F:F,"") -> 1 | AN21: =_xlfn.XLOOKUP(Tabela5[[#This Row],[UUID]],Planilha2!$A:$A,Planilha2!G:G,"") -> 1 | AO21: =_xlfn.XLOOKUP(Tabela5[[#This Row],[UUID]],Planilha2!$A:$A,Planilha2!H:H,"") -> 0 | AP21: =_xlfn.XLOOKUP(Tabela5[[#This Row],[UUID]],Planilha2!$A:$A,Planilha2!I:I,"") -> 0 | AQ21: =_xlfn.XLOOKUP(Tabela5[[#This Row],[UUID]],Planilha2!$A:$A,Planilha2!J:J,"") -> 0 | AR21: =_xlfn.XLOOKUP(Tabela5[[#This Row],[UUID]],Planilha2!$A:$A,Planilha2!K:K,"") -> 0 | AS21: =_xlfn.XLOOKUP(Tabela5[[#This Row],[UUID]],Planilha2!$A:$A,Planilha2!L:L,"") -> 0 | AT21: =_xlfn.XLOOKUP(Tabela5[[#This Row],[UUID]],Planilha2!$A:$A,Planilha2!M:M,"") -> 0 | AU21: =_xlfn.XLOOKUP(Tabela5[[#This Row],[UUID]],Planilha2!$A:$A,Planilha2!N:N,"") -> 1 | AV21: =_xlfn.XLOOKUP(Tabela5[[#This Row],[UUID]],Planilha2!$A:$A,Planilha2!O:O,"") -> 1
A22: COB-242471 | B22: Faturado | C22: 4320722 | D22: 13609424591 | E22: JOAQUIM SIQUEIRA DA SILVA | F22: RUA DA SERRINHA 5 ITACARANHASALVADOR Salvador BA 40713-354 | G22: ADE-13770-Y7W6V9 | H22: 46082 | I22: 202603 | J22: 369.50652 | L22: 369.51 | N22: 90520359 | O22: 46101 | P22: 46111 | R22: 15 | S22: 2 - CPF | T22: Em aberto - Vencido | U22: Em aberto - Vencido | V22: E5OOKMY | W22: 6 | X22: false | Y22: 6 | Z22: Em aberto - Vencido | AA22: ASSOCIAÇÃO BA ? L1 | AB22: 35.686.965/0001-64 - ALEXANDRIA TECH | AC22: Estimado | AE22: 1 a 30 dias | AF22: 21d4813a-c6fc-4a13-b8dd-bd9ec6e50911 | AG22: 46115 | AH22: 1 a 30 dias | AI22: =_xlfn.XLOOKUP(Tabela5[[#This Row],[UUID]],Planilha2!$A:$A,Planilha2!B:B,"") -> 1 | AJ22: =_xlfn.XLOOKUP(Tabela5[[#This Row],[UUID]],Planilha2!$A:$A,Planilha2!C:C,"") -> 1 | AK22: =_xlfn.XLOOKUP(Tabela5[[#This Row],[UUID]],Planilha2!$A:$A,Planilha2!D:D,"") -> 10 | AL22: =_xlfn.XLOOKUP(Tabela5[[#This Row],[UUID]],Planilha2!$A:$A,Planilha2!E:E,"") -> 0 | AM22: =_xlfn.XLOOKUP(Tabela5[[#This Row],[UUID]],Planilha2!$A:$A,Planilha2!F:F,"") -> 1 | AN22: =_xlfn.XLOOKUP(Tabela5[[#This Row],[UUID]],Planilha2!$A:$A,Planilha2!G:G,"") -> 1 | AO22: =_xlfn.XLOOKUP(Tabela5[[#This Row],[UUID]],Planilha2!$A:$A,Planilha2!H:H,"") -> 0 | AP22: =_xlfn.XLOOKUP(Tabela5[[#This Row],[UUID]],Planilha2!$A:$A,Planilha2!I:I,"") -> 0 | AQ22: =_xlfn.XLOOKUP(Tabela5[[#This Row],[UUID]],Planilha2!$A:$A,Planilha2!J:J,"") -> 0 | AR22: =_xlfn.XLOOKUP(Tabela5[[#This Row],[UUID]],Planilha2!$A:$A,Planilha2!K:K,"") -> 0 | AS22: =_xlfn.XLOOKUP(Tabela5[[#This Row],[UUID]],Planilha2!$A:$A,Planilha2!L:L,"") -> 0 | AT22: =_xlfn.XLOOKUP(Tabela5[[#This Row],[UUID]],Planilha2!$A:$A,Planilha2!M:M,"") -> 0 | AU22: =_xlfn.XLOOKUP(Tabela5[[#This Row],[UUID]],Planilha2!$A:$A,Planilha2!N:N,"") -> 1 | AV22: =_xlfn.XLOOKUP(Tabela5[[#This Row],[UUID]],Planilha2!$A:$A,Planilha2!O:O,"") -> 1
A23: COB-125895 | B23: Faturado | C23: 150948667 | D23: 2068774712 | E23: MEYLERLOURDES FERREIRA MIRANDA LEITE | F23: RUA KARINA TATIANE SAMPAIO 60 PROV. OBRA 12000-000 RES ESTORIL / TAUBATE - SP | G23: ADE-12436-P7V0B7 | H23: 45839 | I23: 202507 | J23: 140.76911 | L23: 140.77 | N23: 90364317 | O23: 45916 | P23: 45926 | R23: 200 | S23: 2 - CPF | T23: Em aberto - Vencido | U23: Em aberto - Vencido | V23: 7QJ7R1K | W23: 6 | X23: false | Y23: 6 | Z23: Em aberto - Vencido | AA23: ASSOCIAÇÃO SP-L3 | AB23: 35.686.965/0001-64 - ALEXANDRIA TECH | AE23: 171 a 450 dias | AF23: ffcbc6dd-50fe-4475-a0c9-f22d2c728140 | AG23: 45965 | AH23: Maior que 90 | AI23: =_xlfn.XLOOKUP(Tabela5[[#This Row],[UUID]],Planilha2!$A:$A,Planilha2!B:B,"") -> 0 | AJ23: =_xlfn.XLOOKUP(Tabela5[[#This Row],[UUID]],Planilha2!$A:$A,Planilha2!C:C,"") -> 0 | AK23: =_xlfn.XLOOKUP(Tabela5[[#This Row],[UUID]],Planilha2!$A:$A,Planilha2!D:D,"") -> 0 | AL23: =_xlfn.XLOOKUP(Tabela5[[#This Row],[UUID]],Planilha2!$A:$A,Planilha2!E:E,"") -> 5 | AM23: =_xlfn.XLOOKUP(Tabela5[[#This Row],[UUID]],Planilha2!$A:$A,Planilha2!F:F,"") -> 0 | AN23: =_xlfn.XLOOKUP(Tabela5[[#This Row],[UUID]],Planilha2!$A:$A,Planilha2!G:G,"") -> 0 | AO23: =_xlfn.XLOOKUP(Tabela5[[#This Row],[UUID]],Planilha2!$A:$A,Planilha2!H:H,"") -> 0 | AP23: =_xlfn.XLOOKUP(Tabela5[[#This Row],[UUID]],Planilha2!$A:$A,Planilha2!I:I,"") -> 0 | AQ23: =_xlfn.XLOOKUP(Tabela5[[#This Row],[UUID]],Planilha2!$A:$A,Planilha2!J:J,"") -> 0 | AR23: =_xlfn.XLOOKUP(Tabela5[[#This Row],[UUID]],Planilha2!$A:$A,Planilha2!K:K,"") -> 0 | AS23: =_xlfn.XLOOKUP(Tabela5[[#This Row],[UUID]],Planilha2!$A:$A,Planilha2!L:L,"") -> 0 | AT23: =_xlfn.XLOOKUP(Tabela5[[#This Row],[UUID]],Planilha2!$A:$A,Planilha2!M:M,"") -> 0 | AU23: =_xlfn.XLOOKUP(Tabela5[[#This Row],[UUID]],Planilha2!$A:$A,Planilha2!N:N,"") -> 0 | AV23: =_xlfn.XLOOKUP(Tabela5[[#This Row],[UUID]],Planilha2!$A:$A,Planilha2!O:O,"") -> 0
A24: COB-242467 | B24: Faturado | C24: 30203351 | D24: 82265135534 | E24: ALTAIR EDUARDO SANTANA GOMES | F24: RUA PAU MIUDO 34 Pau Miúdo Euclides da Cunha BA 48500-000 | G24: ADE-13750-N0J4N2 | H24: 46082 | I24: 202603 | J24: 221.19146 | L24: 221.19 | N24: 90520356 | O24: 46101 | P24: 46111 | R24: 15 | S24: 2 - CPF | T24: Em aberto - Vencido | U24: Em aberto - Vencido | V24: LIMD0A9 | W24: 6 | X24: false | Y24: 6 | Z24: Em aberto - Vencido | AA24: ASSOCIAÇÃO BA ? L1 | AB24: 35.686.965/0001-64 - ALEXANDRIA TECH | AC24: Estimado | AE24: 1 a 30 dias | AF24: 701f3a48-9f07-44a6-9386-8487d816d1e7 | AG24: 46115 | AH24: 1 a 30 dias | AI24: =_xlfn.XLOOKUP(Tabela5[[#This Row],[UUID]],Planilha2!$A:$A,Planilha2!B:B,"") -> 1 | AJ24: =_xlfn.XLOOKUP(Tabela5[[#This Row],[UUID]],Planilha2!$A:$A,Planilha2!C:C,"") -> 1 | AK24: =_xlfn.XLOOKUP(Tabela5[[#This Row],[UUID]],Planilha2!$A:$A,Planilha2!D:D,"") -> 12 | AL24: =_xlfn.XLOOKUP(Tabela5[[#This Row],[UUID]],Planilha2!$A:$A,Planilha2!E:E,"") -> 0 | AM24: =_xlfn.XLOOKUP(Tabela5[[#This Row],[UUID]],Planilha2!$A:$A,Planilha2!F:F,"") -> 1 | AN24: =_xlfn.XLOOKUP(Tabela5[[#This Row],[UUID]],Planilha2!$A:$A,Planilha2!G:G,"") -> 1 | AO24: =_xlfn.XLOOKUP(Tabela5[[#This Row],[UUID]],Planilha2!$A:$A,Planilha2!H:H,"") -> 0 | AP24: =_xlfn.XLOOKUP(Tabela5[[#This Row],[UUID]],Planilha2!$A:$A,Planilha2!I:I,"") -> 0 | AQ24: =_xlfn.XLOOKUP(Tabela5[[#This Row],[UUID]],Planilha2!$A:$A,Planilha2!J:J,"") -> 0 | AR24: =_xlfn.XLOOKUP(Tabela5[[#This Row],[UUID]],Planilha2!$A:$A,Planilha2!K:K,"") -> 0 | AS24: =_xlfn.XLOOKUP(Tabela5[[#This Row],[UUID]],Planilha2!$A:$A,Planilha2!L:L,"") -> 0 | AT24: =_xlfn.XLOOKUP(Tabela5[[#This Row],[UUID]],Planilha2!$A:$A,Planilha2!M:M,"") -> 0 | AU24: =_xlfn.XLOOKUP(Tabela5[[#This Row],[UUID]],Planilha2!$A:$A,Planilha2!N:N,"") -> 1 | AV24: =_xlfn.XLOOKUP(Tabela5[[#This Row],[UUID]],Planilha2!$A:$A,Planilha2!O:O,"") -> 1
A25: COB-145312 | B25: Faturado | C25: 37630636 | D25: 376041986 | E25: ALEX SANDRO MIRANDA DE JESUS | F25: R MANOEL RIBAS, 85 NOSSO TETO 16370-000 PROMISSAO - SP | G25: ADE-11673-K1L8Y8 | H25: 45839 | I25: 202507 | J25: 24.08116 | L25: 24.08 | N25: 90364814 | O25: 45918 | P25: 45929 | R25: 197 | S25: 2 - CPF | T25: Em aberto - Vencido | U25: Em aberto - Vencido | V25: A4ASJ7B | W25: 6 | X25: false | Y25: 6 | Z25: Em aberto - Vencido | AA25: ASSOCIACAO SP-L2 | AB25: 35.686.965/0001-64 - ALEXANDRIA TECH | AE25: 171 a 450 dias | AF25: fba0a144-c4d4-4a18-8d90-ba314fbdfadc | AG25: 45929 | AH25: Maior que 90 | AI25: =_xlfn.XLOOKUP(Tabela5[[#This Row],[UUID]],Planilha2!$A:$A,Planilha2!B:B,"") -> 0 | AJ25: =_xlfn.XLOOKUP(Tabela5[[#This Row],[UUID]],Planilha2!$A:$A,Planilha2!C:C,"") -> 0 | AK25: =_xlfn.XLOOKUP(Tabela5[[#This Row],[UUID]],Planilha2!$A:$A,Planilha2!D:D,"") -> 0 | AL25: =_xlfn.XLOOKUP(Tabela5[[#This Row],[UUID]],Planilha2!$A:$A,Planilha2!E:E,"") -> 5 | AM25: =_xlfn.XLOOKUP(Tabela5[[#This Row],[UUID]],Planilha2!$A:$A,Planilha2!F:F,"") -> 0 | AN25: =_xlfn.XLOOKUP(Tabela5[[#This Row],[UUID]],Planilha2!$A:$A,Planilha2!G:G,"") -> 0 | AO25: =_xlfn.XLOOKUP(Tabela5[[#This Row],[UUID]],Planilha2!$A:$A,Planilha2!H:H,"") -> 0 | AP25: =_xlfn.XLOOKUP(Tabela5[[#This Row],[UUID]],Planilha2!$A:$A,Planilha2!I:I,"") -> 0 | AQ25: =_xlfn.XLOOKUP(Tabela5[[#This Row],[UUID]],Planilha2!$A:$A,Planilha2!J:J,"") -> 0 | AR25: =_xlfn.XLOOKUP(Tabela5[[#This Row],[UUID]],Planilha2!$A:$A,Planilha2!K:K,"") -> 0 | AS25: =_xlfn.XLOOKUP(Tabela5[[#This Row],[UUID]],Planilha2!$A:$A,Planilha2!L:L,"") -> 0 | AT25: =_xlfn.XLOOKUP(Tabela5[[#This Row],[UUID]],Planilha2!$A:$A,Planilha2!M:M,"") -> 0 | AU25: =_xlfn.XLOOKUP(Tabela5[[#This Row],[UUID]],Planilha2!$A:$A,Planilha2!N:N,"") -> 0 | AV25: =_xlfn.XLOOKUP(Tabela5[[#This Row],[UUID]],Planilha2!$A:$A,Planilha2!O:O,"") -> 0
A26: COB-242377 | B26: Faturado | C26: 3261505 | D26: 25503693515 | E26: NELTON JOSE LOPES FREIRE | F26: RUA A 2 CENTRO-MATA DE SAO JOAO/MATA DE SAO JOAO Mata de São João BA 48280-000 | G26: ADE-13130-V4K3X8 | H26: 46082 | I26: 202603 | J26: 186.15803 | L26: 186.16 | N26: 90520495 | O26: 46101 | P26: 46111 | R26: 15 | S26: 2 - CPF | T26: Em aberto - Vencido | U26: Em aberto - Vencido | V26: SSGJT1R | W26: 6 | X26: false | Y26: 6 | Z26: Em aberto - Vencido | AA26: ASSOCIAÇÃO BA ? L1 | AB26: 35.686.965/0001-64 - ALEXANDRIA TECH | AC26: Estimado | AE26: 1 a 30 dias | AF26: 4e0cdf25-bc3d-4e05-b42c-82b541814bf6 | AG26: 46115 | AH26: 1 a 30 dias | AI26: =_xlfn.XLOOKUP(Tabela5[[#This Row],[UUID]],Planilha2!$A:$A,Planilha2!B:B,"") -> 1 | AJ26: =_xlfn.XLOOKUP(Tabela5[[#This Row],[UUID]],Planilha2!$A:$A,Planilha2!C:C,"") -> 1 | AK26: =_xlfn.XLOOKUP(Tabela5[[#This Row],[UUID]],Planilha2!$A:$A,Planilha2!D:D,"") -> 1 | AL26: =_xlfn.XLOOKUP(Tabela5[[#This Row],[UUID]],Planilha2!$A:$A,Planilha2!E:E,"") -> 0 | AM26: =_xlfn.XLOOKUP(Tabela5[[#This Row],[UUID]],Planilha2!$A:$A,Planilha2!F:F,"") -> 1 | AN26: =_xlfn.XLOOKUP(Tabela5[[#This Row],[UUID]],Planilha2!$A:$A,Planilha2!G:G,"") -> 1 | AO26: =_xlfn.XLOOKUP(Tabela5[[#This Row],[UUID]],Planilha2!$A:$A,Planilha2!H:H,"") -> 0 | AP26: =_xlfn.XLOOKUP(Tabela5[[#This Row],[UUID]],Planilha2!$A:$A,Planilha2!I:I,"") -> 0 | AQ26: =_xlfn.XLOOKUP(Tabela5[[#This Row],[UUID]],Planilha2!$A:$A,Planilha2!J:J,"") -> 0 | AR26: =_xlfn.XLOOKUP(Tabela5[[#This Row],[UUID]],Planilha2!$A:$A,Planilha2!K:K,"") -> 0 | AS26: =_xlfn.XLOOKUP(Tabela5[[#This Row],[UUID]],Planilha2!$A:$A,Planilha2!L:L,"") -> 0 | AT26: =_xlfn.XLOOKUP(Tabela5[[#This Row],[UUID]],Planilha2!$A:$A,Planilha2!M:M,"") -> 0 | AU26: =_xlfn.XLOOKUP(Tabela5[[#This Row],[UUID]],Planilha2!$A:$A,Planilha2!N:N,"") -> 1 | AV26: =_xlfn.XLOOKUP(Tabela5[[#This Row],[UUID]],Planilha2!$A:$A,Planilha2!O:O,"") -> 1
A27: COB-242353 | B27: Faturado | C27: 4210058 | D27: 78547105549 | E27: ALEX CARLOS TRINDADE BRITO | F27: RUA CRISTOVAO FERREIRA 66 ZZ Ap 1 Boca do Rio Salvador BA 41710-030 | G27: ADE-13030-G5R4W4 | H27: 46082 | I27: 202603 | J27: 199.89663 | L27: 199.9 | N27: 90520465 | O27: 46101 | P27: 46111 | R27: 15 | S27: 2 - CPF | T27: Em aberto - Vencido | U27: Em aberto - Vencido | V27: 8Y36H6M | Y27: 6 | Z27: NA | AA27: ASSOCIAÇÃO BA ? L1 | AB27: 35.686.965/0001-64 - ALEXANDRIA TECH | AC27: Estimado | AE27: 1 a 30 dias | AF27: 5a6df157-18b3-4643-a1c4-2d9d96469901 | AG27: 46115 | AH27: 1 a 30 dias | AI27: =_xlfn.XLOOKUP(Tabela5[[#This Row],[UUID]],Planilha2!$A:$A,Planilha2!B:B,"") -> 1 | AJ27: =_xlfn.XLOOKUP(Tabela5[[#This Row],[UUID]],Planilha2!$A:$A,Planilha2!C:C,"") -> 1 | AK27: =_xlfn.XLOOKUP(Tabela5[[#This Row],[UUID]],Planilha2!$A:$A,Planilha2!D:D,"") -> 1 | AL27: =_xlfn.XLOOKUP(Tabela5[[#This Row],[UUID]],Planilha2!$A:$A,Planilha2!E:E,"") -> 0 | AM27: =_xlfn.XLOOKUP(Tabela5[[#This Row],[UUID]],Planilha2!$A:$A,Planilha2!F:F,"") -> 1 | AN27: =_xlfn.XLOOKUP(Tabela5[[#This Row],[UUID]],Planilha2!$A:$A,Planilha2!G:G,"") -> 1 | AO27: =_xlfn.XLOOKUP(Tabela5[[#This Row],[UUID]],Planilha2!$A:$A,Planilha2!H:H,"") -> 0 | AP27: =_xlfn.XLOOKUP(Tabela5[[#This Row],[UUID]],Planilha2!$A:$A,Planilha2!I:I,"") -> 0 | AQ27: =_xlfn.XLOOKUP(Tabela5[[#This Row],[UUID]],Planilha2!$A:$A,Planilha2!J:J,"") -> 0 | AR27: =_xlfn.XLOOKUP(Tabela5[[#This Row],[UUID]],Planilha2!$A:$A,Planilha2!K:K,"") -> 0 | AS27: =_xlfn.XLOOKUP(Tabela5[[#This Row],[UUID]],Planilha2!$A:$A,Planilha2!L:L,"") -> 0 | AT27: =_xlfn.XLOOKUP(Tabela5[[#This Row],[UUID]],Planilha2!$A:$A,Planilha2!M:M,"") -> 0 | AU27: =_xlfn.XLOOKUP(Tabela5[[#This Row],[UUID]],Planilha2!$A:$A,Planilha2!N:N,"") -> 1 | AV27: =_xlfn.XLOOKUP(Tabela5[[#This Row],[UUID]],Planilha2!$A:$A,Planilha2!O:O,"") -> 1
A28: COB-242347 | B28: Faturado | C28: 3280767 | D28: 15833232520 | E28: CARLOS ANTUNES SILVA PEREIRA | F28: Rua Esbela Costa 0 Medeiros Neto Medeiros Neto BA 45960-000 | G28: ADE-13016-P4B5T7 | H28: 46082 | I28: 202603 | J28: 265.84191 | L28: 265.84 | N28: 90520306 | O28: 46101 | P28: 46111 | R28: 15 | S28: 2 - CPF | T28: Em aberto - Vencido | U28: Em aberto - Vencido | V28: 67W9BRH | W28: 6 | X28: false | Y28: 6 | Z28: Em aberto - Vencido | AA28: ASSOCIAÇÃO BA ? L1 | AB28: 35.686.965/0001-64 - ALEXANDRIA TECH | AC28: Estimado | AE28: 1 a 30 dias | AF28: 8b73fa3c-1273-4a87-8e7f-1331613320a1 | AG28: 46115 | AH28: 1 a 30 dias | AI28: =_xlfn.XLOOKUP(Tabela5[[#This Row],[UUID]],Planilha2!$A:$A,Planilha2!B:B,"") -> 1 | AJ28: =_xlfn.XLOOKUP(Tabela5[[#This Row],[UUID]],Planilha2!$A:$A,Planilha2!C:C,"") -> 1 | AK28: =_xlfn.XLOOKUP(Tabela5[[#This Row],[UUID]],Planilha2!$A:$A,Planilha2!D:D,"") -> 10 | AL28: =_xlfn.XLOOKUP(Tabela5[[#This Row],[UUID]],Planilha2!$A:$A,Planilha2!E:E,"") -> 0 | AM28: =_xlfn.XLOOKUP(Tabela5[[#This Row],[UUID]],Planilha2!$A:$A,Planilha2!F:F,"") -> 1 | AN28: =_xlfn.XLOOKUP(Tabela5[[#This Row],[UUID]],Planilha2!$A:$A,Planilha2!G:G,"") -> 1 | AO28: =_xlfn.XLOOKUP(Tabela5[[#This Row],[UUID]],Planilha2!$A:$A,Planilha2!H:H,"") -> 0 | AP28: =_xlfn.XLOOKUP(Tabela5[[#This Row],[UUID]],Planilha2!$A:$A,Planilha2!I:I,"") -> 0 | AQ28: =_xlfn.XLOOKUP(Tabela5[[#This Row],[UUID]],Planilha2!$A:$A,Planilha2!J:J,"") -> 0 | AR28: =_xlfn.XLOOKUP(Tabela5[[#This Row],[UUID]],Planilha2!$A:$A,Planilha2!K:K,"") -> 0 | AS28: =_xlfn.XLOOKUP(Tabela5[[#This Row],[UUID]],Planilha2!$A:$A,Planilha2!L:L,"") -> 0 | AT28: =_xlfn.XLOOKUP(Tabela5[[#This Row],[UUID]],Planilha2!$A:$A,Planilha2!M:M,"") -> 0 | AU28: =_xlfn.XLOOKUP(Tabela5[[#This Row],[UUID]],Planilha2!$A:$A,Planilha2!N:N,"") -> 1 | AV28: =_xlfn.XLOOKUP(Tabela5[[#This Row],[UUID]],Planilha2!$A:$A,Planilha2!O:O,"") -> 1
A29: COB-242338 | B29: Faturado | C29: 9809902 | D29: 2759407560 | E29: RILDO MARQUES DE ARAUJO FILHO | F29: RUA COLONIA BOA UNIAO 99 Reserva Parque Camaçari BA 42821-900 | G29: ADE-12992-R9Y8N0 | H29: 46082 | I29: 202603 | J29: 315.9878 | L29: 315.99 | N29: 90520494 | O29: 46101 | P29: 46111 | R29: 15 | S29: 2 - CPF | T29: Em aberto - Vencido | U29: Em aberto - Vencido | V29: 6KH4DY5 | W29: 6 | X29: false | Y29: 6 | Z29: Em aberto - Vencido | AA29: ASSOCIAÇÃO BA ? L1 | AB29: 35.686.965/0001-64 - ALEXANDRIA TECH | AC29: Estimado | AE29: 1 a 30 dias | AF29: 5de7aebf-cef5-49dd-b92a-5439104b3a49 | AG29: 46117 | AH29: 1 a 30 dias | AI29: =_xlfn.XLOOKUP(Tabela5[[#This Row],[UUID]],Planilha2!$A:$A,Planilha2!B:B,"") -> 1 | AJ29: =_xlfn.XLOOKUP(Tabela5[[#This Row],[UUID]],Planilha2!$A:$A,Planilha2!C:C,"") -> 1 | AK29: =_xlfn.XLOOKUP(Tabela5[[#This Row],[UUID]],Planilha2!$A:$A,Planilha2!D:D,"") -> 1 | AL29: =_xlfn.XLOOKUP(Tabela5[[#This Row],[UUID]],Planilha2!$A:$A,Planilha2!E:E,"") -> 0 | AM29: =_xlfn.XLOOKUP(Tabela5[[#This Row],[UUID]],Planilha2!$A:$A,Planilha2!F:F,"") -> 1 | AN29: =_xlfn.XLOOKUP(Tabela5[[#This Row],[UUID]],Planilha2!$A:$A,Planilha2!G:G,"") -> 0 | AO29: =_xlfn.XLOOKUP(Tabela5[[#This Row],[UUID]],Planilha2!$A:$A,Planilha2!H:H,"") -> 0 | AP29: =_xlfn.XLOOKUP(Tabela5[[#This Row],[UUID]],Planilha2!$A:$A,Planilha2!I:I,"") -> 0 | AQ29: =_xlfn.XLOOKUP(Tabela5[[#This Row],[UUID]],Planilha2!$A:$A,Planilha2!J:J,"") -> 0 | AR29: =_xlfn.XLOOKUP(Tabela5[[#This Row],[UUID]],Planilha2!$A:$A,Planilha2!K:K,"") -> 0 | AS29: =_xlfn.XLOOKUP(Tabela5[[#This Row],[UUID]],Planilha2!$A:$A,Planilha2!L:L,"") -> 0 | AT29: =_xlfn.XLOOKUP(Tabela5[[#This Row],[UUID]],Planilha2!$A:$A,Planilha2!M:M,"") -> 1 | AU29: =_xlfn.XLOOKUP(Tabela5[[#This Row],[UUID]],Planilha2!$A:$A,Planilha2!N:N,"") -> 1 | AV29: =_xlfn.XLOOKUP(Tabela5[[#This Row],[UUID]],Planilha2!$A:$A,Planilha2!O:O,"") -> 1
A30: COB-242332 | B30: Faturado | C30: 2639964 | D30: 91328110559 | E30: CICERO CONCEICAO DA HORA | F30: RUA MELLO LEITE 30 CENTRO Ituberá BA 45435-000 | G30: ADE-12940-K4M4L2 | H30: 46082 | I30: 202603 | J30: 279.58051 | L30: 279.58 | N30: 90520464 | O30: 46101 | P30: 46111 | R30: 15 | S30: 2 - CPF | T30: Em aberto - Vencido | U30: Em aberto - Vencido | V30: UK8F9T0 | W30: 6 | X30: false | Y30: 6 | Z30: Em aberto - Vencido | AA30: ASSOCIAÇÃO BA ? L1 | AB30: 35.686.965/0001-64 - ALEXANDRIA TECH | AC30: Estimado | AE30: 1 a 30 dias | AF30: 3633625c-63e3-4b5e-8083-e5fe427051b3 | AG30: 46120 | AH30: 1 a 30 dias | AI30: =_xlfn.XLOOKUP(Tabela5[[#This Row],[UUID]],Planilha2!$A:$A,Planilha2!B:B,"") -> 1 | AJ30: =_xlfn.XLOOKUP(Tabela5[[#This Row],[UUID]],Planilha2!$A:$A,Planilha2!C:C,"") -> 1 | AK30: =_xlfn.XLOOKUP(Tabela5[[#This Row],[UUID]],Planilha2!$A:$A,Planilha2!D:D,"") -> 1 | AL30: =_xlfn.XLOOKUP(Tabela5[[#This Row],[UUID]],Planilha2!$A:$A,Planilha2!E:E,"") -> 0 | AM30: =_xlfn.XLOOKUP(Tabela5[[#This Row],[UUID]],Planilha2!$A:$A,Planilha2!F:F,"") -> 1 | AN30: =_xlfn.XLOOKUP(Tabela5[[#This Row],[UUID]],Planilha2!$A:$A,Planilha2!G:G,"") -> 0 | AO30: =_xlfn.XLOOKUP(Tabela5[[#This Row],[UUID]],Planilha2!$A:$A,Planilha2!H:H,"") -> 0 | AP30: =_xlfn.XLOOKUP(Tabela5[[#This Row],[UUID]],Planilha2!$A:$A,Planilha2!I:I,"") -> 0 | AQ30: =_xlfn.XLOOKUP(Tabela5[[#This Row],[UUID]],Planilha2!$A:$A,Planilha2!J:J,"") -> 0 | AR30: =_xlfn.XLOOKUP(Tabela5[[#This Row],[UUID]],Planilha2!$A:$A,Planilha2!K:K,"") -> 0 | AS30: =_xlfn.XLOOKUP(Tabela5[[#This Row],[UUID]],Planilha2!$A:$A,Planilha2!L:L,"") -> 0 | AT30: =_xlfn.XLOOKUP(Tabela5[[#This Row],[UUID]],Planilha2!$A:$A,Planilha2!M:M,"") -> 0 | AU30: =_xlfn.XLOOKUP(Tabela5[[#This Row],[UUID]],Planilha2!$A:$A,Planilha2!N:N,"") -> 1 | AV30: =_xlfn.XLOOKUP(Tabela5[[#This Row],[UUID]],Planilha2!$A:$A,Planilha2!O:O,"") -> 1
A31: COB-242326 | B31: Faturado | C31: 10322348 | D31: 94738220578 | E31: JAILSON GUIMARAES PINHEIRO | F31: Rua Melvin Jones 147 AP- 1104 ED ACQUA MARINE RESIDENCIAL Jardim Armação Salvador BA 41750-010 | G31: ADE-12898-Z7W9R9 | H31: 46082 | I31: 202603 | J31: 514.51057 | L31: 514.51 | N31: 90520233 | O31: 46101 | P31: 46111 | R31: 15 | S31: 2 - CPF | T31: Em aberto - Vencido | U31: Em aberto - Vencido | V31: S8J68XB | W31: 6 | X31: false | Y31: 6 | Z31: Em aberto - Vencido | AA31: ASSOCIAÇÃO BA ? L1 | AB31: 35.686.965/0001-64 - ALEXANDRIA TECH | AC31: Estimado | AE31: 1 a 30 dias | AF31: 57da7b8d-f0e3-480d-9c91-b54adbb3b304 | AG31: 46115 | AH31: 1 a 30 dias | AI31: =_xlfn.XLOOKUP(Tabela5[[#This Row],[UUID]],Planilha2!$A:$A,Planilha2!B:B,"") -> 1 | AJ31: =_xlfn.XLOOKUP(Tabela5[[#This Row],[UUID]],Planilha2!$A:$A,Planilha2!C:C,"") -> 1 | AK31: =_xlfn.XLOOKUP(Tabela5[[#This Row],[UUID]],Planilha2!$A:$A,Planilha2!D:D,"") -> 10 | AL31: =_xlfn.XLOOKUP(Tabela5[[#This Row],[UUID]],Planilha2!$A:$A,Planilha2!E:E,"") -> 0 | AM31: =_xlfn.XLOOKUP(Tabela5[[#This Row],[UUID]],Planilha2!$A:$A,Planilha2!F:F,"") -> 1 | AN31: =_xlfn.XLOOKUP(Tabela5[[#This Row],[UUID]],Planilha2!$A:$A,Planilha2!G:G,"") -> 1 | AO31: =_xlfn.XLOOKUP(Tabela5[[#This Row],[UUID]],Planilha2!$A:$A,Planilha2!H:H,"") -> 0 | AP31: =_xlfn.XLOOKUP(Tabela5[[#This Row],[UUID]],Planilha2!$A:$A,Planilha2!I:I,"") -> 0 | AQ31: =_xlfn.XLOOKUP(Tabela5[[#This Row],[UUID]],Planilha2!$A:$A,Planilha2!J:J,"") -> 0 | AR31: =_xlfn.XLOOKUP(Tabela5[[#This Row],[UUID]],Planilha2!$A:$A,Planilha2!K:K,"") -> 0 | AS31: =_xlfn.XLOOKUP(Tabela5[[#This Row],[UUID]],Planilha2!$A:$A,Planilha2!L:L,"") -> 0 | AT31: =_xlfn.XLOOKUP(Tabela5[[#This Row],[UUID]],Planilha2!$A:$A,Planilha2!M:M,"") -> 0 | AU31: =_xlfn.XLOOKUP(Tabela5[[#This Row],[UUID]],Planilha2!$A:$A,Planilha2!N:N,"") -> 1 | AV31: =_xlfn.XLOOKUP(Tabela5[[#This Row],[UUID]],Planilha2!$A:$A,Planilha2!O:O,"") -> 1
